Workbook

Sheet Setup
A1: About this File
A3: This workbook will summarize and analyze data downloaded from the Retirement Administrator dashboard in Ellucian's Employee Self Service. 1) Update green cells on this tab with correct data. 2) Paste in cell O1 of the data tab the records from the Retire Administrator dasbboard download (Age 50+) 3) Refresh the Pivot table on the Pivot tab 4) IMPORTANT! Make sure formulas (blue cells) copy down to the last record on both the Data (columns A:N) and Pivot (A:B) tabs Conditional formatting will highlight cells red (Data M:N or Pivot A:B) if an employee med the FICA threshold and has exceeded the standard contribution limit in pretax deductions. NOTE: As of April 2026 the retirement dashboard only contains contributions finalized in Payroll. Due to this limitation, you may need to find a way to extract current payroll contributions and add them on the same data worksheet, under the data from the retirement dashboard, keeping data in the correct columns. Original workbook created by Steven Clark at Utah State University. - License and Copyright: https://github.com/KL4RKS/banner-scripts/blob/main/LICENSE - Addional Secure 2.0 files and instructions can be found in the following GitHub folder: https://github.com/KL4RKS/banner-scripts/tree/main/hr/secure2
A4: Spreadsheet modified to meet the needs of [INSTITUTION] by [ExcelGuruNameHere]
A6: Current Year Variables
A8: 24500 | D8: <-- Standard Contribution Limit
A9: 150000 | D9: <-- Prior Year FICA Threshhold
A10: 50 | D10: <-- Age catch-ups begin at age
A12: Deduction Groups
A14: Main Traditional | D14: Main Roth | G14: 457 Traditional | J14: 457 Roth
A15: Code | B15: Description | D15: Code | E15: Description | G15: Code | H15: Description | J15: Code | K15: Description
A16: 651 | B16: Employee Federal TSP % | D16: 565 | E16: Employee Roth TIAA 403 $ | G16: 652 | H16: Employee URS 457 % | J16: 571 | K16: Employee Roth TIAA 457 $
A17: 656 | B17: Employee Fidelity 403B % | D17: 665 | E17: Employee Roth TIAA 403 % | G17: 654 | H17: Employee TIAA 457 % | J17: 572 | K17: Employee Roth Fidelity 457 $
A18: 657 | B18: Employee TIAA 403B % | D18: 666 | E18: Employee Roth Fidelity 403 % | G18: 569 | H18: Employee Fidelity 457 $ | J18: 574 | K18: Employee Roth URS 457 $
A19: 507 | B19: Employer URS 401K T1 | D19: 570 | E19: Employee Roth Fed TSP | G19: 669 | H19: Employee Fidelity 457 % | J19: 671 | K19: Employee Roth TIAA 457 %
A20: 551 | B20: Employee Federal TSP $ | D20: 573 | E20: Employee Roth URS 401 $ | G20: 552 | H20: Employee URS 457 $ | J20: 672 | K20: Employee Roth Fidelity 457 %
A21: 553 | B21: Employee URS 401K $ | D21: 673 | E21: Employee Roth URS 401 % | G21: 554 | H21: Employee TIAA 457 $ | J21: 674 | K21: Employee Roth URS 457 %
A22: 556 | B22: Employee Fidelity 403B $ | D22: 566 | E22: Employee Roth Fidelity 403 $
A23: 541 | B23: Empr Pub Safety Tier2 DC 401K
A24: 653 | B24: Employee URS 401K %
A25: 557 | B25: Employee TIAA 403B $
A26: 531 | B26: Empr URS T2 DC 401k
A27: 536 | B27: Empr Pub Safety Tier 2DB 401K
A28: 518 | B28: Employer Fed TSP
A29: 504 | B29: Employer URS 401K T2

Sheet Data
A1: ID | B1: Name | C1: Age | D1: High Earner | E1: Main Pretax | F1: Main Roth | G1: 457 Pretax | H1: 457 Roth | I1: Sum Main Pretax | J1: Sum Main Roth | K1: Sum 457 Pretax | L1: Sum 457 Roth | M1: Excess Main Pretax | N1: Excess 457 Pretax | O1: Banner Id | P1: Name | Q1: Age | R1: Benefit Code | S1: Benefit Description | T1: Combined Limit Description | U1: Employee Amount YTD | V1: Employer Amount YTD | W1: Applicable Gross Amount YTD | X1: Current Year FICA Gross | Y1: Prior Year FICA Gross
A2: =IF(O2="",A1,O2) -> A00000001 | B2: =IF(P2="",B1,P2) -> Aaron J. Whitfield | C2: =IF(Q2="",C1,Q2) -> 59 | D2: =IF(AND(Y2>=Setup!$A$9,C2>=Setup!$A$10),"Y","N") -> N | E2: =IF(COUNTIF(Setup!A:A, R2) > 0, U2, 0) -> 0 | F2: =IF(COUNTIF(Setup!D:D, R2) > 0, U2, 0) -> 0 | G2: =IF(COUNTIF(Setup!G:G, R2) > 0, U2, 0) -> 0 | H2: =IF(COUNTIF(Setup!J:J, R2) > 0, U2, 0) -> 0 | I2: =SUMIFS(E:E,$A:$A,$O2) -> 1036.8 | J2: =SUMIFS(F:F,$A:$A,$O2) -> 0 | K2: =SUMIFS(G:G,$A:$A,$O2) -> 0 | L2: =SUMIFS(H:H,$A:$A,$O2) -> 0 | M2: =IF(D2="Y",MAX(0,I2-Setup!$A$8),0) -> 0 | N2: =IF(D2="Y",MAX(0,K2-Setup!$A$8),0) -> 0 | O2: A00000001 | P2: Aaron J. Whitfield | Q2: 59 | R2: 503 | S2: Tier 2 Utah Retirement Systems Employee Contribution | U2: 279.9 | V2: 0 | W2: 34559.28 | X2: 33634.44 | Y2: 46174.8
A3: =IF(O3="",A2,O3) -> A00000001 | B3: =IF(P3="",B2,P3) -> Aaron J. Whitfield | C3: =IF(Q3="",C2,Q3) -> 59 | D3: =IF(AND(Y3>=Setup!$A$9,C3>=Setup!$A$10),"Y","N") -> N | E3: =IF(COUNTIF(Setup!A:A, R3) > 0, U3, 0) -> 0 | F3: =IF(COUNTIF(Setup!D:D, R3) > 0, U3, 0) -> 0 | G3: =IF(COUNTIF(Setup!G:G, R3) > 0, U3, 0) -> 0 | H3: =IF(COUNTIF(Setup!J:J, R3) > 0, U3, 0) -> 0 | I3: =SUMIFS(E:E,$A:$A,$O3) -> 0 | J3: =SUMIFS(F:F,$A:$A,$O3) -> 0 | K3: =SUMIFS(G:G,$A:$A,$O3) -> 0 | L3: =SUMIFS(H:H,$A:$A,$O3) -> 0 | M3: =IF(D3="Y",MAX(0,I3-Setup!$A$8),0) -> 0 | N3: =IF(D3="Y",MAX(0,K3-Setup!$A$8),0) -> 0 | R3: 505 | S3: Tier 2 Utah Retirement Systems Employer Contribution | U3: 0 | V3: 1153.14 | W3: 34559.28 | X3: 33634.44 | Y3: 46174.8
A4: =IF(O4="",A3,O4) -> A00000001 | B4: =IF(P4="",B3,P4) -> Aaron J. Whitfield | C4: =IF(Q4="",C3,Q4) -> 59 | D4: =IF(AND(Y4>=Setup!$A$9,C4>=Setup!$A$10),"Y","N") -> N | E4: =IF(COUNTIF(Setup!A:A, R4) > 0, U4, 0) -> 0 | F4: =IF(COUNTIF(Setup!D:D, R4) > 0, U4, 0) -> 0 | G4: =IF(COUNTIF(Setup!G:G, R4) > 0, U4, 0) -> 0 | H4: =IF(COUNTIF(Setup!J:J, R4) > 0, U4, 0) -> 0 | I4: =SUMIFS(E:E,$A:$A,$O4) -> 0 | J4: =SUMIFS(F:F,$A:$A,$O4) -> 0 | K4: =SUMIFS(G:G,$A:$A,$O4) -> 0 | L4: =SUMIFS(H:H,$A:$A,$O4) -> 0 | M4: =IF(D4="Y",MAX(0,I4-Setup!$A$8),0) -> 0 | N4: =IF(D4="Y",MAX(0,K4-Setup!$A$8),0) -> 0 | R4: 504 | S4: Tier 2 Utah Retirement Systems 401(k) Employer Contribution | U4: 0 | V4: 0 | W4: 34559.28 | X4: 33634.44 | Y4: 46174.8
A5: =IF(O5="",A4,O5) -> A00000001 | B5: =IF(P5="",B4,P5) -> Aaron J. Whitfield | C5: =IF(Q5="",C4,Q5) -> 59 | D5: =IF(AND(Y5>=Setup!$A$9,C5>=Setup!$A$10),"Y","N") -> N | E5: =IF(COUNTIF(Setup!A:A, R5) > 0, U5, 0) -> 345.6 | F5: =IF(COUNTIF(Setup!D:D, R5) > 0, U5, 0) -> 0 | G5: =IF(COUNTIF(Setup!G:G, R5) > 0, U5, 0) -> 0 | H5: =IF(COUNTIF(Setup!J:J, R5) > 0, U5, 0) -> 0 | I5: =SUMIFS(E:E,$A:$A,$O5) -> 0 | J5: =SUMIFS(F:F,$A:$A,$O5) -> 0 | K5: =SUMIFS(G:G,$A:$A,$O5) -> 0 | L5: =SUMIFS(H:H,$A:$A,$O5) -> 0 | M5: =IF(D5="Y",MAX(0,I5-Setup!$A$8),0) -> 0 | N5: =IF(D5="Y",MAX(0,K5-Setup!$A$8),0) -> 0 | R5: 657 | S5: TIAA Retirement 403(b) Employee Contribution | T5: RT_C50, Catch-up over 50 | U5: 345.6 | V5: 0 | W5: 34559.28 | X5: 33634.44 | Y5: 46174.8
A6: =IF(O6="",A5,O6) -> A00000001 | B6: =IF(P6="",B5,P6) -> Aaron J. Whitfield | C6: =IF(Q6="",C5,Q6) -> 59 | D6: =IF(AND(Y6>=Setup!$A$9,C6>=Setup!$A$10),"Y","N") -> N | E6: =IF(COUNTIF(Setup!A:A, R6) > 0, U6, 0) -> 691.2 | F6: =IF(COUNTIF(Setup!D:D, R6) > 0, U6, 0) -> 0 | G6: =IF(COUNTIF(Setup!G:G, R6) > 0, U6, 0) -> 0 | H6: =IF(COUNTIF(Setup!J:J, R6) > 0, U6, 0) -> 0 | I6: =SUMIFS(E:E,$A:$A,$O6) -> 0 | J6: =SUMIFS(F:F,$A:$A,$O6) -> 0 | K6: =SUMIFS(G:G,$A:$A,$O6) -> 0 | L6: =SUMIFS(H:H,$A:$A,$O6) -> 0 | M6: =IF(D6="Y",MAX(0,I6-Setup!$A$8),0) -> 0 | N6: =IF(D6="Y",MAX(0,K6-Setup!$A$8),0) -> 0 | R6: 653 | S6: Utah Retirement Systems 401(k) Employee Contribution | T6: RT_C50, Catch-up over 50 | U6: 691.2 | V6: 0 | W6: 34559.28 | X6: 33634.44 | Y6: 46174.8
A7: =IF(O7="",A6,O7) -> A00000002 | B7: =IF(P7="",B6,P7) -> Benjamin A. Foster | C7: =IF(Q7="",C6,Q7) -> 59 | D7: =IF(AND(Y7>=Setup!$A$9,C7>=Setup!$A$10),"Y","N") -> N | E7: =IF(COUNTIF(Setup!A:A, R7) > 0, U7, 0) -> 0 | F7: =IF(COUNTIF(Setup!D:D, R7) > 0, U7, 0) -> 0 | G7: =IF(COUNTIF(Setup!G:G, R7) > 0, U7, 0) -> 0 | H7: =IF(COUNTIF(Setup!J:J, R7) > 0, U7, 0) -> 0 | I7: =SUMIFS(E:E,$A:$A,$O7) -> 489.6 | J7: =SUMIFS(F:F,$A:$A,$O7) -> 0 | K7: =SUMIFS(G:G,$A:$A,$O7) -> 0 | L7: =SUMIFS(H:H,$A:$A,$O7) -> 0 | M7: =IF(D7="Y",MAX(0,I7-Setup!$A$8),0) -> 0 | N7: =IF(D7="Y",MAX(0,K7-Setup!$A$8),0) -> 0 | O7: A00000002 | P7: Benjamin A. Foster | Q7: 59 | R7: 504 | S7: Tier 2 Utah Retirement Systems 401(k) Employer Contribution | U7: 0 | V7: 0 | W7: 48958.56 | X7: 46451.52 | Y7: 63863.63
A8: =IF(O8="",A7,O8) -> A00000002 | B8: =IF(P8="",B7,P8) -> Benjamin A. Foster | C8: =IF(Q8="",C7,Q8) -> 59 | D8: =IF(AND(Y8>=Setup!$A$9,C8>=Setup!$A$10),"Y","N") -> N | E8: =IF(COUNTIF(Setup!A:A, R8) > 0, U8, 0) -> 0 | F8: =IF(COUNTIF(Setup!D:D, R8) > 0, U8, 0) -> 0 | G8: =IF(COUNTIF(Setup!G:G, R8) > 0, U8, 0) -> 0 | H8: =IF(COUNTIF(Setup!J:J, R8) > 0, U8, 0) -> 0 | I8: =SUMIFS(E:E,$A:$A,$O8) -> 0 | J8: =SUMIFS(F:F,$A:$A,$O8) -> 0 | K8: =SUMIFS(G:G,$A:$A,$O8) -> 0 | L8: =SUMIFS(H:H,$A:$A,$O8) -> 0 | M8: =IF(D8="Y",MAX(0,I8-Setup!$A$8),0) -> 0 | N8: =IF(D8="Y",MAX(0,K8-Setup!$A$8),0) -> 0 | R8: 503 | S8: Tier 2 Utah Retirement Systems Employee Contribution | U8: 396.54 | V8: 0 | W8: 48958.56 | X8: 46451.52 | Y8: 63863.63
A9: =IF(O9="",A8,O9) -> A00000002 | B9: =IF(P9="",B8,P9) -> Benjamin A. Foster | C9: =IF(Q9="",C8,Q9) -> 59 | D9: =IF(AND(Y9>=Setup!$A$9,C9>=Setup!$A$10),"Y","N") -> N | E9: =IF(COUNTIF(Setup!A:A, R9) > 0, U9, 0) -> 0 | F9: =IF(COUNTIF(Setup!D:D, R9) > 0, U9, 0) -> 0 | G9: =IF(COUNTIF(Setup!G:G, R9) > 0, U9, 0) -> 0 | H9: =IF(COUNTIF(Setup!J:J, R9) > 0, U9, 0) -> 0 | I9: =SUMIFS(E:E,$A:$A,$O9) -> 0 | J9: =SUMIFS(F:F,$A:$A,$O9) -> 0 | K9: =SUMIFS(G:G,$A:$A,$O9) -> 0 | L9: =SUMIFS(H:H,$A:$A,$O9) -> 0 | M9: =IF(D9="Y",MAX(0,I9-Setup!$A$8),0) -> 0 | N9: =IF(D9="Y",MAX(0,K9-Setup!$A$8),0) -> 0 | R9: 505 | S9: Tier 2 Utah Retirement Systems Employer Contribution | U9: 0 | V9: 1633.59 | W9: 48958.56 | X9: 46451.52 | Y9: 63863.63
A10: =IF(O10="",A9,O10) -> A00000002 | B10: =IF(P10="",B9,P10) -> Benjamin A. Foster | C10: =IF(Q10="",C9,Q10) -> 59 | D10: =IF(AND(Y10>=Setup!$A$9,C10>=Setup!$A$10),"Y","N") -> N | E10: =IF(COUNTIF(Setup!A:A, R10) > 0, U10, 0) -> 489.6 | F10: =IF(COUNTIF(Setup!D:D, R10) > 0, U10, 0) -> 0 | G10: =IF(COUNTIF(Setup!G:G, R10) > 0, U10, 0) -> 0 | H10: =IF(COUNTIF(Setup!J:J, R10) > 0, U10, 0) -> 0 | I10: =SUMIFS(E:E,$A:$A,$O10) -> 0 | J10: =SUMIFS(F:F,$A:$A,$O10) -> 0 | K10: =SUMIFS(G:G,$A:$A,$O10) -> 0 | L10: =SUMIFS(H:H,$A:$A,$O10) -> 0 | M10: =IF(D10="Y",MAX(0,I10-Setup!$A$8),0) -> 0 | N10: =IF(D10="Y",MAX(0,K10-Setup!$A$8),0) -> 0 | R10: 657 | S10: TIAA Retirement 403(b) Employee Contribution | T10: RT_C50, Catch-up over 50 | U10: 489.6 | V10: 0 | W10: 48958.56 | X10: 46451.52 | Y10: 63863.63
A11: =IF(O11="",A10,O11) -> A00000003 | B11: =IF(P11="",B10,P11) -> Claire Elizabeth Monroe | C11: =IF(Q11="",C10,Q11) -> 57 | D11: =IF(AND(Y11>=Setup!$A$9,C11>=Setup!$A$10),"Y","N") -> Y | E11: =IF(COUNTIF(Setup!A:A, R11) > 0, U11, 0) -> 0 | F11: =IF(COUNTIF(Setup!D:D, R11) > 0, U11, 0) -> 0 | G11: =IF(COUNTIF(Setup!G:G, R11) > 0, U11, 0) -> 0 | H11: =IF(COUNTIF(Setup!J:J, R11) > 0, U11, 0) -> 0 | I11: =SUMIFS(E:E,$A:$A,$O11) -> 0 | J11: =SUMIFS(F:F,$A:$A,$O11) -> 28733.24 | K11: =SUMIFS(G:G,$A:$A,$O11) -> 26300 | L11: =SUMIFS(H:H,$A:$A,$O11) -> 4373.84 | M11: =IF(D11="Y",MAX(0,I11-Setup!$A$8),0) -> 0 | N11: =IF(D11="Y",MAX(0,K11-Setup!$A$8),0) -> 1800 | O11: A00000003 | P11: Claire Elizabeth Monroe | Q11: 57 | R11: 521 | S11: TIAA Retirement Employer Contribution | T11: RT_EE_AF, ER Contr EE Hire After 1/31/21 | U11: 0 | V11: 5250.66 | W11: 221858.28 | X11: 214802.88 | Y11: 176100
A12: =IF(O12="",A11,O12) -> A00000003 | B12: =IF(P12="",B11,P12) -> Claire Elizabeth Monroe | C12: =IF(Q12="",C11,Q12) -> 57 | D12: =IF(AND(Y12>=Setup!$A$9,C12>=Setup!$A$10),"Y","N") -> Y | E12: =IF(COUNTIF(Setup!A:A, R12) > 0, U12, 0) -> 0 | F12: =IF(COUNTIF(Setup!D:D, R12) > 0, U12, 0) -> 0 | G12: =IF(COUNTIF(Setup!G:G, R12) > 0, U12, 0) -> 0 | H12: =IF(COUNTIF(Setup!J:J, R12) > 0, U12, 0) -> 4173.84 | I12: =SUMIFS(E:E,$A:$A,$O12) -> 0 | J12: =SUMIFS(F:F,$A:$A,$O12) -> 0 | K12: =SUMIFS(G:G,$A:$A,$O12) -> 0 | L12: =SUMIFS(H:H,$A:$A,$O12) -> 0 | M12: =IF(D12="Y",MAX(0,I12-Setup!$A$8),0) -> 0 | N12: =IF(D12="Y",MAX(0,K12-Setup!$A$8),0) -> 0 | R12: 571 | S12: TIAA Retirement Roth 457(b) Employee Contribution | T12: RT_C50, Catch-up over 50 | U12: 4173.84 | V12: 0 | W12: 148505.52 | X12: 214802.88 | Y12: 176100
A13: =IF(O13="",A12,O13) -> A00000003 | B13: =IF(P13="",B12,P13) -> Claire Elizabeth Monroe | C13: =IF(Q13="",C12,Q13) -> 57 | D13: =IF(AND(Y13>=Setup!$A$9,C13>=Setup!$A$10),"Y","N") -> Y | E13: =IF(COUNTIF(Setup!A:A, R13) > 0, U13, 0) -> 0 | F13: =IF(COUNTIF(Setup!D:D, R13) > 0, U13, 0) -> 0 | G13: =IF(COUNTIF(Setup!G:G, R13) > 0, U13, 0) -> 24500 | H13: =IF(COUNTIF(Setup!J:J, R13) > 0, U13, 0) -> 0 | I13: =SUMIFS(E:E,$A:$A,$O13) -> 0 | J13: =SUMIFS(F:F,$A:$A,$O13) -> 0 | K13: =SUMIFS(G:G,$A:$A,$O13) -> 0 | L13: =SUMIFS(H:H,$A:$A,$O13) -> 0 | M13: =IF(D13="Y",MAX(0,I13-Setup!$A$8),0) -> 0 | N13: =IF(D13="Y",MAX(0,K13-Setup!$A$8),0) -> 0 | R13: 554 | S13: TIAA Retirement 457(b) Employee Contribution | T13: RT_C50, Catch-up over 50 | U13: 24500 | V13: 0 | W13: 256889.04 | X13: 214802.88 | Y13: 176100
A14: =IF(O14="",A13,O14) -> A00000003 | B14: =IF(P14="",B13,P14) -> Claire Elizabeth Monroe | C14: =IF(Q14="",C13,Q14) -> 57 | D14: =IF(AND(Y14>=Setup!$A$9,C14>=Setup!$A$10),"Y","N") -> Y | E14: =IF(COUNTIF(Setup!A:A, R14) > 0, U14, 0) -> 0 | F14: =IF(COUNTIF(Setup!D:D, R14) > 0, U14, 0) -> 26733.24 | G14: =IF(COUNTIF(Setup!G:G, R14) > 0, U14, 0) -> 0 | H14: =IF(COUNTIF(Setup!J:J, R14) > 0, U14, 0) -> 0 | I14: =SUMIFS(E:E,$A:$A,$O14) -> 0 | J14: =SUMIFS(F:F,$A:$A,$O14) -> 0 | K14: =SUMIFS(G:G,$A:$A,$O14) -> 0 | L14: =SUMIFS(H:H,$A:$A,$O14) -> 0 | M14: =IF(D14="Y",MAX(0,I14-Setup!$A$8),0) -> 0 | N14: =IF(D14="Y",MAX(0,K14-Setup!$A$8),0) -> 0 | R14: 565 | S14: TIAA Retirement Roth 403(b) Employee Contribution | T14: RT_C50, Catch-up over 50 | U14: 26733.24 | V14: 0 | W14: 256889.04 | X14: 214802.88 | Y14: 176100
A15: =IF(O15="",A14,O15) -> A00000004 | B15: =IF(P15="",B14,P15) -> Daniel R. Holloway | C15: =IF(Q15="",C14,Q15) -> 53 | D15: =IF(AND(Y15>=Setup!$A$9,C15>=Setup!$A$10),"Y","N") -> N | E15: =IF(COUNTIF(Setup!A:A, R15) > 0, U15, 0) -> 0 | F15: =IF(COUNTIF(Setup!D:D, R15) > 0, U15, 0) -> 0 | G15: =IF(COUNTIF(Setup!G:G, R15) > 0, U15, 0) -> 0 | H15: =IF(COUNTIF(Setup!J:J, R15) > 0, U15, 0) -> 0 | I15: =SUMIFS(E:E,$A:$A,$O15) -> 2295.76 | J15: =SUMIFS(F:F,$A:$A,$O15) -> 750 | K15: =SUMIFS(G:G,$A:$A,$O15) -> 0 | L15: =SUMIFS(H:H,$A:$A,$O15) -> 0 | M15: =IF(D15="Y",MAX(0,I15-Setup!$A$8),0) -> 0 | N15: =IF(D15="Y",MAX(0,K15-Setup!$A$8),0) -> 0 | O15: A00000004 | P15: Daniel R. Holloway | Q15: 53 | R15: 521 | S15: TIAA Retirement Employer Contribution | T15: RT_EE_AF, ER Contr EE Hire After 1/31/21 | U15: 0 | V15: 299.1 | W15: 63190.44 | X15: 57253.32 | Y15: 82002.66
A16: =IF(O16="",A15,O16) -> A00000004 | B16: =IF(P16="",B15,P16) -> Daniel R. Holloway | C16: =IF(Q16="",C15,Q16) -> 53 | D16: =IF(AND(Y16>=Setup!$A$9,C16>=Setup!$A$10),"Y","N") -> N | E16: =IF(COUNTIF(Setup!A:A, R16) > 0, U16, 0) -> 0 | F16: =IF(COUNTIF(Setup!D:D, R16) > 0, U16, 0) -> 450 | G16: =IF(COUNTIF(Setup!G:G, R16) > 0, U16, 0) -> 0 | H16: =IF(COUNTIF(Setup!J:J, R16) > 0, U16, 0) -> 0 | I16: =SUMIFS(E:E,$A:$A,$O16) -> 0 | J16: =SUMIFS(F:F,$A:$A,$O16) -> 0 | K16: =SUMIFS(G:G,$A:$A,$O16) -> 0 | L16: =SUMIFS(H:H,$A:$A,$O16) -> 0 | M16: =IF(D16="Y",MAX(0,I16-Setup!$A$8),0) -> 0 | N16: =IF(D16="Y",MAX(0,K16-Setup!$A$8),0) -> 0 | R16: 566 | S16: Fidelity Retirement Roth 403(b) Employee Contribution | T16: RT_C50, Catch-up over 50 | U16: 450 | V16: 0 | W16: 65134.68 | X16: 57253.32 | Y16: 82002.66
A17: =IF(O17="",A16,O17) -> A00000004 | B17: =IF(P17="",B16,P17) -> Daniel R. Holloway | C17: =IF(Q17="",C16,Q17) -> 53 | D17: =IF(AND(Y17>=Setup!$A$9,C17>=Setup!$A$10),"Y","N") -> N | E17: =IF(COUNTIF(Setup!A:A, R17) > 0, U17, 0) -> 0 | F17: =IF(COUNTIF(Setup!D:D, R17) > 0, U17, 0) -> 0 | G17: =IF(COUNTIF(Setup!G:G, R17) > 0, U17, 0) -> 0 | H17: =IF(COUNTIF(Setup!J:J, R17) > 0, U17, 0) -> 0 | I17: =SUMIFS(E:E,$A:$A,$O17) -> 0 | J17: =SUMIFS(F:F,$A:$A,$O17) -> 0 | K17: =SUMIFS(G:G,$A:$A,$O17) -> 0 | L17: =SUMIFS(H:H,$A:$A,$O17) -> 0 | M17: =IF(D17="Y",MAX(0,I17-Setup!$A$8),0) -> 0 | N17: =IF(D17="Y",MAX(0,K17-Setup!$A$8),0) -> 0 | R17: 525 | S17: Fidelity Retirement Employer Contribution | T17: RT_EE_AF, ER Contr EE Hire After 1/31/21 | U17: 0 | V17: 1196.4 | W17: 63190.44 | X17: 57253.32 | Y17: 82002.66
A18: =IF(O18="",A17,O18) -> A00000004 | B18: =IF(P18="",B17,P18) -> Daniel R. Holloway | C18: =IF(Q18="",C17,Q18) -> 53 | D18: =IF(AND(Y18>=Setup!$A$9,C18>=Setup!$A$10),"Y","N") -> N | E18: =IF(COUNTIF(Setup!A:A, R18) > 0, U18, 0) -> 1895.76 | F18: =IF(COUNTIF(Setup!D:D, R18) > 0, U18, 0) -> 0 | G18: =IF(COUNTIF(Setup!G:G, R18) > 0, U18, 0) -> 0 | H18: =IF(COUNTIF(Setup!J:J, R18) > 0, U18, 0) -> 0 | I18: =SUMIFS(E:E,$A:$A,$O18) -> 0 | J18: =SUMIFS(F:F,$A:$A,$O18) -> 0 | K18: =SUMIFS(G:G,$A:$A,$O18) -> 0 | L18: =SUMIFS(H:H,$A:$A,$O18) -> 0 | M18: =IF(D18="Y",MAX(0,I18-Setup!$A$8),0) -> 0 | N18: =IF(D18="Y",MAX(0,K18-Setup!$A$8),0) -> 0 | R18: 657 | S18: TIAA Retirement 403(b) Employee Contribution | T18: RT_C50, Catch-up over 50 | U18: 1895.76 | V18: 0 | W18: 63190.44 | X18: 57253.32 | Y18: 82002.66
A19: =IF(O19="",A18,O19) -> A00000005 | B19: =IF(P19="",B18,P19) -> Emily J. Harrington | C19: =IF(Q19="",C18,Q19) -> 54 | D19: =IF(AND(Y19>=Setup!$A$9,C19>=Setup!$A$10),"Y","N") -> Y | E19: =IF(COUNTIF(Setup!A:A, R19) > 0, U19, 0) -> 0 | F19: =IF(COUNTIF(Setup!D:D, R19) > 0, U19, 0) -> 0 | G19: =IF(COUNTIF(Setup!G:G, R19) > 0, U19, 0) -> 0 | H19: =IF(COUNTIF(Setup!J:J, R19) > 0, U19, 0) -> 0 | I19: =SUMIFS(E:E,$A:$A,$O19) -> 3663 | J19: =SUMIFS(F:F,$A:$A,$O19) -> 4500 | K19: =SUMIFS(G:G,$A:$A,$O19) -> 4500 | L19: =SUMIFS(H:H,$A:$A,$O19) -> 900 | M19: =IF(D19="Y",MAX(0,I19-Setup!$A$8),0) -> 0 | N19: =IF(D19="Y",MAX(0,K19-Setup!$A$8),0) -> 0 | O19: A00000005 | P19: Emily J. Harrington | Q19: 54 | R19: 525 | S19: Fidelity Retirement Employer Contribution | T19: RT_EE_AF, ER Contr EE Hire After 1/31/21 | U19: 0 | V19: 2600.73 | W19: 122099.94 | X19: 122125.38 | Y19: 167802.86
A20: =IF(O20="",A19,O20) -> A00000005 | B20: =IF(P20="",B19,P20) -> Emily J. Harrington | C20: =IF(Q20="",C19,Q20) -> 54 | D20: =IF(AND(Y20>=Setup!$A$9,C20>=Setup!$A$10),"Y","N") -> Y | E20: =IF(COUNTIF(Setup!A:A, R20) > 0, U20, 0) -> 0 | F20: =IF(COUNTIF(Setup!D:D, R20) > 0, U20, 0) -> 0 | G20: =IF(COUNTIF(Setup!G:G, R20) > 0, U20, 0) -> 0 | H20: =IF(COUNTIF(Setup!J:J, R20) > 0, U20, 0) -> 900 | I20: =SUMIFS(E:E,$A:$A,$O20) -> 0 | J20: =SUMIFS(F:F,$A:$A,$O20) -> 0 | K20: =SUMIFS(G:G,$A:$A,$O20) -> 0 | L20: =SUMIFS(H:H,$A:$A,$O20) -> 0 | M20: =IF(D20="Y",MAX(0,I20-Setup!$A$8),0) -> 0 | N20: =IF(D20="Y",MAX(0,K20-Setup!$A$8),0) -> 0 | R20: 572 | S20: Fidelity Retirement Roth 457(b) Employee Contribution | T20: RT_C50, Catch-up over 50 | U20: 900 | V20: 0 | W20: 122099.94 | X20: 122125.38 | Y20: 167802.86
A21: =IF(O21="",A20,O21) -> A00000005 | B21: =IF(P21="",B20,P21) -> Emily J. Harrington | C21: =IF(Q21="",C20,Q21) -> 54 | D21: =IF(AND(Y21>=Setup!$A$9,C21>=Setup!$A$10),"Y","N") -> Y | E21: =IF(COUNTIF(Setup!A:A, R21) > 0, U21, 0) -> 3663 | F21: =IF(COUNTIF(Setup!D:D, R21) > 0, U21, 0) -> 0 | G21: =IF(COUNTIF(Setup!G:G, R21) > 0, U21, 0) -> 0 | H21: =IF(COUNTIF(Setup!J:J, R21) > 0, U21, 0) -> 0 | I21: =SUMIFS(E:E,$A:$A,$O21) -> 0 | J21: =SUMIFS(F:F,$A:$A,$O21) -> 0 | K21: =SUMIFS(G:G,$A:$A,$O21) -> 0 | L21: =SUMIFS(H:H,$A:$A,$O21) -> 0 | M21: =IF(D21="Y",MAX(0,I21-Setup!$A$8),0) -> 0 | N21: =IF(D21="Y",MAX(0,K21-Setup!$A$8),0) -> 0 | R21: 657 | S21: TIAA Retirement 403(b) Employee Contribution | T21: RT_C50, Catch-up over 50 | U21: 3663 | V21: 0 | W21: 122099.94 | X21: 122125.38 | Y21: 167802.86
A22: =IF(O22="",A21,O22) -> A00000005 | B22: =IF(P22="",B21,P22) -> Emily J. Harrington | C22: =IF(Q22="",C21,Q22) -> 54 | D22: =IF(AND(Y22>=Setup!$A$9,C22>=Setup!$A$10),"Y","N") -> Y | E22: =IF(COUNTIF(Setup!A:A, R22) > 0, U22, 0) -> 0 | F22: =IF(COUNTIF(Setup!D:D, R22) > 0, U22, 0) -> 4500 | G22: =IF(COUNTIF(Setup!G:G, R22) > 0, U22, 0) -> 0 | H22: =IF(COUNTIF(Setup!J:J, R22) > 0, U22, 0) -> 0 | I22: =SUMIFS(E:E,$A:$A,$O22) -> 0 | J22: =SUMIFS(F:F,$A:$A,$O22) -> 0 | K22: =SUMIFS(G:G,$A:$A,$O22) -> 0 | L22: =SUMIFS(H:H,$A:$A,$O22) -> 0 | M22: =IF(D22="Y",MAX(0,I22-Setup!$A$8),0) -> 0 | N22: =IF(D22="Y",MAX(0,K22-Setup!$A$8),0) -> 0 | R22: 566 | S22: Fidelity Retirement Roth 403(b) Employee Contribution | T22: RT_C50, Catch-up over 50 | U22: 4500 | V22: 0 | W22: 122099.94 | X22: 122125.38 | Y22: 167802.86
A23: =IF(O23="",A22,O23) -> A00000005 | B23: =IF(P23="",B22,P23) -> Emily J. Harrington | C23: =IF(Q23="",C22,Q23) -> 54 | D23: =IF(AND(Y23>=Setup!$A$9,C23>=Setup!$A$10),"Y","N") -> Y | E23: =IF(COUNTIF(Setup!A:A, R23) > 0, U23, 0) -> 0 | F23: =IF(COUNTIF(Setup!D:D, R23) > 0, U23, 0) -> 0 | G23: =IF(COUNTIF(Setup!G:G, R23) > 0, U23, 0) -> 4500 | H23: =IF(COUNTIF(Setup!J:J, R23) > 0, U23, 0) -> 0 | I23: =SUMIFS(E:E,$A:$A,$O23) -> 0 | J23: =SUMIFS(F:F,$A:$A,$O23) -> 0 | K23: =SUMIFS(G:G,$A:$A,$O23) -> 0 | L23: =SUMIFS(H:H,$A:$A,$O23) -> 0 | M23: =IF(D23="Y",MAX(0,I23-Setup!$A$8),0) -> 0 | N23: =IF(D23="Y",MAX(0,K23-Setup!$A$8),0) -> 0 | R23: 569 | S23: Fidelity Retirement 457(b) Employee Contribution | T23: RT_C50, Catch-up over 50 | U23: 4500 | V23: 0 | W23: 122099.94 | X23: 122125.38 | Y23: 167802.86
A24: =IF(O24="",A23,O24) -> A00000005 | B24: =IF(P24="",B23,P24) -> Emily J. Harrington | C24: =IF(Q24="",C23,Q24) -> 54 | D24: =IF(AND(Y24>=Setup!$A$9,C24>=Setup!$A$10),"Y","N") -> Y | E24: =IF(COUNTIF(Setup!A:A, R24) > 0, U24, 0) -> 0 | F24: =IF(COUNTIF(Setup!D:D, R24) > 0, U24, 0) -> 0 | G24: =IF(COUNTIF(Setup!G:G, R24) > 0, U24, 0) -> 0 | H24: =IF(COUNTIF(Setup!J:J, R24) > 0, U24, 0) -> 0 | I24: =SUMIFS(E:E,$A:$A,$O24) -> 0 | J24: =SUMIFS(F:F,$A:$A,$O24) -> 0 | K24: =SUMIFS(G:G,$A:$A,$O24) -> 0 | L24: =SUMIFS(H:H,$A:$A,$O24) -> 0 | M24: =IF(D24="Y",MAX(0,I24-Setup!$A$8),0) -> 0 | N24: =IF(D24="Y",MAX(0,K24-Setup!$A$8),0) -> 0 | R24: 521 | S24: TIAA Retirement Employer Contribution | T24: RT_EE_AF, ER Contr EE Hire After 1/31/21 | U24: 0 | V24: 288.96 | W24: 122099.94 | X24: 122125.38 | Y24: 167802.86
A25: =IF(O25="",A24,O25) -> A00000006 | B25: =IF(P25="",B24,P25) -> Hannah Lowell Reed | C25: =IF(Q25="",C24,Q25) -> 53 | D25: =IF(AND(Y25>=Setup!$A$9,C25>=Setup!$A$10),"Y","N") -> N | E25: =IF(COUNTIF(Setup!A:A, R25) > 0, U25, 0) -> 0 | F25: =IF(COUNTIF(Setup!D:D, R25) > 0, U25, 0) -> 0 | G25: =IF(COUNTIF(Setup!G:G, R25) > 0, U25, 0) -> 0 | H25: =IF(COUNTIF(Setup!J:J, R25) > 0, U25, 0) -> 0 | I25: =SUMIFS(E:E,$A:$A,$O25) -> 1270.44 | J25: =SUMIFS(F:F,$A:$A,$O25) -> 0 | K25: =SUMIFS(G:G,$A:$A,$O25) -> 1242 | L25: =SUMIFS(H:H,$A:$A,$O25) -> 0 | M25: =IF(D25="Y",MAX(0,I25-Setup!$A$8),0) -> 0 | N25: =IF(D25="Y",MAX(0,K25-Setup!$A$8),0) -> 0 | O25: A00000006 | P25: Hannah Lowell Reed | Q25: 53 | R25: 504 | S25: Tier 2 Utah Retirement Systems 401(k) Employer Contribution | U25: 0 | V25: 0 | W25: 31762.44 | X25: 29031.12 | Y25: 41058.08
A26: =IF(O26="",A25,O26) -> A00000006 | B26: =IF(P26="",B25,P26) -> Hannah Lowell Reed | C26: =IF(Q26="",C25,Q26) -> 53 | D26: =IF(AND(Y26>=Setup!$A$9,C26>=Setup!$A$10),"Y","N") -> N | E26: =IF(COUNTIF(Setup!A:A, R26) > 0, U26, 0) -> 0 | F26: =IF(COUNTIF(Setup!D:D, R26) > 0, U26, 0) -> 0 | G26: =IF(COUNTIF(Setup!G:G, R26) > 0, U26, 0) -> 1242 | H26: =IF(COUNTIF(Setup!J:J, R26) > 0, U26, 0) -> 0 | I26: =SUMIFS(E:E,$A:$A,$O26) -> 0 | J26: =SUMIFS(F:F,$A:$A,$O26) -> 0 | K26: =SUMIFS(G:G,$A:$A,$O26) -> 0 | L26: =SUMIFS(H:H,$A:$A,$O26) -> 0 | M26: =IF(D26="Y",MAX(0,I26-Setup!$A$8),0) -> 0 | N26: =IF(D26="Y",MAX(0,K26-Setup!$A$8),0) -> 0 | R26: 569 | S26: Fidelity Retirement 457(b) Employee Contribution | T26: RT_C50, Catch-up over 50 | U26: 1242 | V26: 0 | W26: 32831.34 | X26: 29031.12 | Y26: 41058.08
A27: =IF(O27="",A26,O27) -> A00000006 | B27: =IF(P27="",B26,P27) -> Hannah Lowell Reed | C27: =IF(Q27="",C26,Q27) -> 53 | D27: =IF(AND(Y27>=Setup!$A$9,C27>=Setup!$A$10),"Y","N") -> N | E27: =IF(COUNTIF(Setup!A:A, R27) > 0, U27, 0) -> 1270.44 | F27: =IF(COUNTIF(Setup!D:D, R27) > 0, U27, 0) -> 0 | G27: =IF(COUNTIF(Setup!G:G, R27) > 0, U27, 0) -> 0 | H27: =IF(COUNTIF(Setup!J:J, R27) > 0, U27, 0) -> 0 | I27: =SUMIFS(E:E,$A:$A,$O27) -> 0 | J27: =SUMIFS(F:F,$A:$A,$O27) -> 0 | K27: =SUMIFS(G:G,$A:$A,$O27) -> 0 | L27: =SUMIFS(H:H,$A:$A,$O27) -> 0 | M27: =IF(D27="Y",MAX(0,I27-Setup!$A$8),0) -> 0 | N27: =IF(D27="Y",MAX(0,K27-Setup!$A$8),0) -> 0 | R27: 656 | S27: Fidelity Retirement 403(b) Employee Contribution | T27: RT_C50, Catch-up over 50 | U27: 1270.44 | V27: 0 | W27: 31762.44 | X27: 29031.12 | Y27: 41058.08
A28: =IF(O28="",A27,O28) -> A00000006 | B28: =IF(P28="",B27,P28) -> Hannah Lowell Reed | C28: =IF(Q28="",C27,Q28) -> 53 | D28: =IF(AND(Y28>=Setup!$A$9,C28>=Setup!$A$10),"Y","N") -> N | E28: =IF(COUNTIF(Setup!A:A, R28) > 0, U28, 0) -> 0 | F28: =IF(COUNTIF(Setup!D:D, R28) > 0, U28, 0) -> 0 | G28: =IF(COUNTIF(Setup!G:G, R28) > 0, U28, 0) -> 0 | H28: =IF(COUNTIF(Setup!J:J, R28) > 0, U28, 0) -> 0 | I28: =SUMIFS(E:E,$A:$A,$O28) -> 0 | J28: =SUMIFS(F:F,$A:$A,$O28) -> 0 | K28: =SUMIFS(G:G,$A:$A,$O28) -> 0 | L28: =SUMIFS(H:H,$A:$A,$O28) -> 0 | M28: =IF(D28="Y",MAX(0,I28-Setup!$A$8),0) -> 0 | N28: =IF(D28="Y",MAX(0,K28-Setup!$A$8),0) -> 0 | R28: 505 | S28: Tier 2 Utah Retirement Systems Employer Contribution | U28: 0 | V28: 1059.81 | W28: 31762.44 | X28: 29031.12 | Y28: 41058.08
A29: =IF(O29="",A28,O29) -> A00000006 | B29: =IF(P29="",B28,P29) -> Hannah Lowell Reed | C29: =IF(Q29="",C28,Q29) -> 53 | D29: =IF(AND(Y29>=Setup!$A$9,C29>=Setup!$A$10),"Y","N") -> N | E29: =IF(COUNTIF(Setup!A:A, R29) > 0, U29, 0) -> 0 | F29: =IF(COUNTIF(Setup!D:D, R29) > 0, U29, 0) -> 0 | G29: =IF(COUNTIF(Setup!G:G, R29) > 0, U29, 0) -> 0 | H29: =IF(COUNTIF(Setup!J:J, R29) > 0, U29, 0) -> 0 | I29: =SUMIFS(E:E,$A:$A,$O29) -> 0 | J29: =SUMIFS(F:F,$A:$A,$O29) -> 0 | K29: =SUMIFS(G:G,$A:$A,$O29) -> 0 | L29: =SUMIFS(H:H,$A:$A,$O29) -> 0 | M29: =IF(D29="Y",MAX(0,I29-Setup!$A$8),0) -> 0 | N29: =IF(D29="Y",MAX(0,K29-Setup!$A$8),0) -> 0 | R29: 503 | S29: Tier 2 Utah Retirement Systems Employee Contribution | U29: 257.22 | V29: 0 | W29: 31762.44 | X29: 29031.12 | Y29: 41058.08
A30: =IF(O30="",A29,O30) -> A00000006 | B30: =IF(P30="",B29,P30) -> Hannah Lowell Reed | C30: =IF(Q30="",C29,Q30) -> 53 | D30: =IF(AND(Y30>=Setup!$A$9,C30>=Setup!$A$10),"Y","N") -> N | E30: =IF(COUNTIF(Setup!A:A, R30) > 0, U30, 0) -> 0 | F30: =IF(COUNTIF(Setup!D:D, R30) > 0, U30, 0) -> 0 | G30: =IF(COUNTIF(Setup!G:G, R30) > 0, U30, 0) -> 0 | H30: =IF(COUNTIF(Setup!J:J, R30) > 0, U30, 0) -> 0 | I30: =SUMIFS(E:E,$A:$A,$O30) -> 0 | J30: =SUMIFS(F:F,$A:$A,$O30) -> 0 | K30: =SUMIFS(G:G,$A:$A,$O30) -> 0 | L30: =SUMIFS(H:H,$A:$A,$O30) -> 0 | M30: =IF(D30="Y",MAX(0,I30-Setup!$A$8),0) -> 0 | N30: =IF(D30="Y",MAX(0,K30-Setup!$A$8),0) -> 0 | R30: 506 | S30: Tier 1 Utah Retirement Systems Employer Contribution | U30: 0 | V30: 1743.91 | W30: 47154.06 | X30: 44173.14 | Y30: 61698.36
A31: =IF(O31="",A30,O31) -> A00000007 | B31: =IF(P31="",B30,P31) -> Isaac P. Nakamura | C31: =IF(Q31="",C30,Q31) -> 52 | D31: =IF(AND(Y31>=Setup!$A$9,C31>=Setup!$A$10),"Y","N") -> Y | E31: =IF(COUNTIF(Setup!A:A, R31) > 0, U31, 0) -> 0 | F31: =IF(COUNTIF(Setup!D:D, R31) > 0, U31, 0) -> 0 | G31: =IF(COUNTIF(Setup!G:G, R31) > 0, U31, 0) -> 15750 | H31: =IF(COUNTIF(Setup!J:J, R31) > 0, U31, 0) -> 0 | I31: =SUMIFS(E:E,$A:$A,$O31) -> 0 | J31: =SUMIFS(F:F,$A:$A,$O31) -> 0 | K31: =SUMIFS(G:G,$A:$A,$O31) -> 15750 | L31: =SUMIFS(H:H,$A:$A,$O31) -> 0 | M31: =IF(D31="Y",MAX(0,I31-Setup!$A$8),0) -> 0 | N31: =IF(D31="Y",MAX(0,K31-Setup!$A$8),0) -> 0 | O31: A00000007 | P31: Isaac P. Nakamura | Q31: 52 | R31: 569 | S31: Fidelity Retirement 457(b) Employee Contribution | T31: RT_C50, Catch-up over 50 | U31: 15750 | V31: 0 | W31: 186159.6 | X31: 174183.48 | Y31: 176100
A32: =IF(O32="",A31,O32) -> A00000007 | B32: =IF(P32="",B31,P32) -> Isaac P. Nakamura | C32: =IF(Q32="",C31,Q32) -> 52 | D32: =IF(AND(Y32>=Setup!$A$9,C32>=Setup!$A$10),"Y","N") -> Y | E32: =IF(COUNTIF(Setup!A:A, R32) > 0, U32, 0) -> 0 | F32: =IF(COUNTIF(Setup!D:D, R32) > 0, U32, 0) -> 0 | G32: =IF(COUNTIF(Setup!G:G, R32) > 0, U32, 0) -> 0 | H32: =IF(COUNTIF(Setup!J:J, R32) > 0, U32, 0) -> 0 | I32: =SUMIFS(E:E,$A:$A,$O32) -> 0 | J32: =SUMIFS(F:F,$A:$A,$O32) -> 0 | K32: =SUMIFS(G:G,$A:$A,$O32) -> 0 | L32: =SUMIFS(H:H,$A:$A,$O32) -> 0 | M32: =IF(D32="Y",MAX(0,I32-Setup!$A$8),0) -> 0 | N32: =IF(D32="Y",MAX(0,K32-Setup!$A$8),0) -> 0 | R32: 572 | S32: Fidelity Retirement Roth 457(b) Employee Contribution | T32: RT_C50, Catch-up over 50 | U32: 0 | V32: 0 | W32: 186159.6 | X32: 174183.48 | Y32: 176100
A33: =IF(O33="",A32,O33) -> A00000007 | B33: =IF(P33="",B32,P33) -> Isaac P. Nakamura | C33: =IF(Q33="",C32,Q33) -> 52 | D33: =IF(AND(Y33>=Setup!$A$9,C33>=Setup!$A$10),"Y","N") -> Y | E33: =IF(COUNTIF(Setup!A:A, R33) > 0, U33, 0) -> 0 | F33: =IF(COUNTIF(Setup!D:D, R33) > 0, U33, 0) -> 0 | G33: =IF(COUNTIF(Setup!G:G, R33) > 0, U33, 0) -> 0 | H33: =IF(COUNTIF(Setup!J:J, R33) > 0, U33, 0) -> 0 | I33: =SUMIFS(E:E,$A:$A,$O33) -> 0 | J33: =SUMIFS(F:F,$A:$A,$O33) -> 0 | K33: =SUMIFS(G:G,$A:$A,$O33) -> 0 | L33: =SUMIFS(H:H,$A:$A,$O33) -> 0 | M33: =IF(D33="Y",MAX(0,I33-Setup!$A$8),0) -> 0 | N33: =IF(D33="Y",MAX(0,K33-Setup!$A$8),0) -> 0 | R33: 525 | S33: Fidelity Retirement Employer Contribution | T33: RT_EE_BF, ER Contr EE Hire Before 2/1/21 | U33: 0 | V33: 4182 | W33: 176704.2 | X33: 174183.48 | Y33: 176100
A34: =IF(O34="",A33,O34) -> A00000008 | B34: =IF(P34="",B33,P34) -> Jordan Blake Thompson | C34: =IF(Q34="",C33,Q34) -> 51 | D34: =IF(AND(Y34>=Setup!$A$9,C34>=Setup!$A$10),"Y","N") -> N | E34: =IF(COUNTIF(Setup!A:A, R34) > 0, U34, 0) -> 0 | F34: =IF(COUNTIF(Setup!D:D, R34) > 0, U34, 0) -> 0 | G34: =IF(COUNTIF(Setup!G:G, R34) > 0, U34, 0) -> 10706.22 | H34: =IF(COUNTIF(Setup!J:J, R34) > 0, U34, 0) -> 0 | I34: =SUMIFS(E:E,$A:$A,$O34) -> 1595.52 | J34: =SUMIFS(F:F,$A:$A,$O34) -> 0 | K34: =SUMIFS(G:G,$A:$A,$O34) -> 21412.44 | L34: =SUMIFS(H:H,$A:$A,$O34) -> 0 | M34: =IF(D34="Y",MAX(0,I34-Setup!$A$8),0) -> 0 | N34: =IF(D34="Y",MAX(0,K34-Setup!$A$8),0) -> 0 | O34: A00000008 | P34: Jordan Blake Thompson | Q34: 51 | R34: 569 | S34: Fidelity Retirement 457(b) Employee Contribution | T34: RT_C50, Catch-up over 50 | U34: 10706.22 | V34: 0 | W34: 53181.72 | X34: 52929.72 | Y34: 32964.88
A35: =IF(O35="",A34,O35) -> A00000008 | B35: =IF(P35="",B34,P35) -> Jordan Blake Thompson | C35: =IF(Q35="",C34,Q35) -> 51 | D35: =IF(AND(Y35>=Setup!$A$9,C35>=Setup!$A$10),"Y","N") -> N | E35: =IF(COUNTIF(Setup!A:A, R35) > 0, U35, 0) -> 1595.52 | F35: =IF(COUNTIF(Setup!D:D, R35) > 0, U35, 0) -> 0 | G35: =IF(COUNTIF(Setup!G:G, R35) > 0, U35, 0) -> 0 | H35: =IF(COUNTIF(Setup!J:J, R35) > 0, U35, 0) -> 0 | I35: =SUMIFS(E:E,$A:$A,$O35) -> 0 | J35: =SUMIFS(F:F,$A:$A,$O35) -> 0 | K35: =SUMIFS(G:G,$A:$A,$O35) -> 0 | L35: =SUMIFS(H:H,$A:$A,$O35) -> 0 | M35: =IF(D35="Y",MAX(0,I35-Setup!$A$8),0) -> 0 | N35: =IF(D35="Y",MAX(0,K35-Setup!$A$8),0) -> 0 | R35: 657 | S35: TIAA Retirement 403(b) Employee Contribution | T35: RT_C50, Catch-up over 50 | U35: 1595.52 | V35: 0 | W35: 53181.72 | X35: 52929.72 | Y35: 32964.88
A36: =IF(O36="",A35,O36) -> A00000008 | B36: =IF(P36="",B35,P36) -> Jordan Blake Thompson | C36: =IF(Q36="",C35,Q36) -> 51 | D36: =IF(AND(Y36>=Setup!$A$9,C36>=Setup!$A$10),"Y","N") -> N | E36: =IF(COUNTIF(Setup!A:A, R36) > 0, U36, 0) -> 0 | F36: =IF(COUNTIF(Setup!D:D, R36) > 0, U36, 0) -> 0 | G36: =IF(COUNTIF(Setup!G:G, R36) > 0, U36, 0) -> 0 | H36: =IF(COUNTIF(Setup!J:J, R36) > 0, U36, 0) -> 0 | I36: =SUMIFS(E:E,$A:$A,$O36) -> 0 | J36: =SUMIFS(F:F,$A:$A,$O36) -> 0 | K36: =SUMIFS(G:G,$A:$A,$O36) -> 0 | L36: =SUMIFS(H:H,$A:$A,$O36) -> 0 | M36: =IF(D36="Y",MAX(0,I36-Setup!$A$8),0) -> 0 | N36: =IF(D36="Y",MAX(0,K36-Setup!$A$8),0) -> 0 | R36: 521 | S36: TIAA Retirement Employer Contribution | T36: RT_EE_AF, ER Contr EE Hire After 1/31/21 | U36: 0 | V36: 629.31 | W36: 53181.72 | X36: 52929.72 | Y36: 32964.88
A37: =IF(O37="",A36,O37) -> A00000008 | B37: =IF(P37="",B36,P37) -> Jordan Blake Thompson | C37: =IF(Q37="",C36,Q37) -> 51 | D37: =IF(AND(Y37>=Setup!$A$9,C37>=Setup!$A$10),"Y","N") -> N | E37: =IF(COUNTIF(Setup!A:A, R37) > 0, U37, 0) -> 0 | F37: =IF(COUNTIF(Setup!D:D, R37) > 0, U37, 0) -> 0 | G37: =IF(COUNTIF(Setup!G:G, R37) > 0, U37, 0) -> 0 | H37: =IF(COUNTIF(Setup!J:J, R37) > 0, U37, 0) -> 0 | I37: =SUMIFS(E:E,$A:$A,$O37) -> 0 | J37: =SUMIFS(F:F,$A:$A,$O37) -> 0 | K37: =SUMIFS(G:G,$A:$A,$O37) -> 0 | L37: =SUMIFS(H:H,$A:$A,$O37) -> 0 | M37: =IF(D37="Y",MAX(0,I37-Setup!$A$8),0) -> 0 | N37: =IF(D37="Y",MAX(0,K37-Setup!$A$8),0) -> 0 | R37: 525 | S37: Fidelity Retirement Employer Contribution | T37: RT_EE_AF, ER Contr EE Hire After 1/31/21 | U37: 0 | V37: 629.31 | W37: 53181.72 | X37: 52929.72 | Y37: 32964.88
A38: =IF(O38="",A37,O38) -> A00000008 | B38: =IF(P38="",B37,P38) -> Jordan Blake Thompson | C38: =IF(Q38="",C37,Q38) -> 51 | D38: =IF(AND(Y38>=Setup!$A$9,C38>=Setup!$A$10),"Y","N") -> N | E38: =IF(COUNTIF(Setup!A:A, R38) > 0, U38, 0) -> 0 | F38: =IF(COUNTIF(Setup!D:D, R38) > 0, U38, 0) -> 0 | G38: =IF(COUNTIF(Setup!G:G, R38) > 0, U38, 0) -> 10706.22 | H38: =IF(COUNTIF(Setup!J:J, R38) > 0, U38, 0) -> 0 | I38: =SUMIFS(E:E,$A:$A,$O38) -> 0 | J38: =SUMIFS(F:F,$A:$A,$O38) -> 0 | K38: =SUMIFS(G:G,$A:$A,$O38) -> 0 | L38: =SUMIFS(H:H,$A:$A,$O38) -> 0 | M38: =IF(D38="Y",MAX(0,I38-Setup!$A$8),0) -> 0 | N38: =IF(D38="Y",MAX(0,K38-Setup!$A$8),0) -> 0 | R38: 554 | S38: TIAA Retirement 457(b) Employee Contribution | T38: RT_C50, Catch-up over 50 | U38: 10706.22 | V38: 0 | W38: 53181.72 | X38: 52929.72 | Y38: 32964.88
A39: =IF(O39="",A38,O39) -> A00000009 | B39: =IF(P39="",B38,P39) -> Lina M. Alvarez | C39: =IF(Q39="",C38,Q39) -> 81 | D39: =IF(AND(Y39>=Setup!$A$9,C39>=Setup!$A$10),"Y","N") -> N | E39: =IF(COUNTIF(Setup!A:A, R39) > 0, U39, 0) -> 0 | F39: =IF(COUNTIF(Setup!D:D, R39) > 0, U39, 0) -> 0 | G39: =IF(COUNTIF(Setup!G:G, R39) > 0, U39, 0) -> 0 | H39: =IF(COUNTIF(Setup!J:J, R39) > 0, U39, 0) -> 0 | I39: =SUMIFS(E:E,$A:$A,$O39) -> 14517 | J39: =SUMIFS(F:F,$A:$A,$O39) -> 0 | K39: =SUMIFS(G:G,$A:$A,$O39) -> 14571 | L39: =SUMIFS(H:H,$A:$A,$O39) -> 0 | M39: =IF(D39="Y",MAX(0,I39-Setup!$A$8),0) -> 0 | N39: =IF(D39="Y",MAX(0,K39-Setup!$A$8),0) -> 0 | O39: A00000009 | P39: Lina M. Alvarez | Q39: 81 | R39: 521 | S39: TIAA Retirement Employer Contribution | T39: RT_EE_BF, ER Contr EE Hire Before 2/1/21 | U39: 0 | V39: 1368.57 | W39: 57826.44 | X39: 56706.48 | Y39: 78802.11
A40: =IF(O40="",A39,O40) -> A00000009 | B40: =IF(P40="",B39,P40) -> Lina M. Alvarez | C40: =IF(Q40="",C39,Q40) -> 81 | D40: =IF(AND(Y40>=Setup!$A$9,C40>=Setup!$A$10),"Y","N") -> N | E40: =IF(COUNTIF(Setup!A:A, R40) > 0, U40, 0) -> 0 | F40: =IF(COUNTIF(Setup!D:D, R40) > 0, U40, 0) -> 0 | G40: =IF(COUNTIF(Setup!G:G, R40) > 0, U40, 0) -> 7380 | H40: =IF(COUNTIF(Setup!J:J, R40) > 0, U40, 0) -> 0 | I40: =SUMIFS(E:E,$A:$A,$O40) -> 0 | J40: =SUMIFS(F:F,$A:$A,$O40) -> 0 | K40: =SUMIFS(G:G,$A:$A,$O40) -> 0 | L40: =SUMIFS(H:H,$A:$A,$O40) -> 0 | M40: =IF(D40="Y",MAX(0,I40-Setup!$A$8),0) -> 0 | N40: =IF(D40="Y",MAX(0,K40-Setup!$A$8),0) -> 0 | R40: 569 | S40: Fidelity Retirement 457(b) Employee Contribution | T40: RT_C50, Catch-up over 50 | U40: 7380 | V40: 0 | W40: 57826.44 | X40: 56706.48 | Y40: 78802.11
...

Sheet Pivot
A2: V FORMULAS V | C2: V Pivot Table V
A3: Main Excess | B3: 457 Excess | C3: Row Labels | D3: Sum of Main Pretax | E3: Sum of 457 Pretax
A4: =IFERROR(IF(VLOOKUP($C4,Data!$A:$D,4,0)="N",0,MAX(0,D4-Setup!$A$8)),) -> 0 | B4: =IFERROR(IF(VLOOKUP($C4,Data!$A:$D,4,0)="N",0,MAX(0,E4-Setup!$A$8)),) -> 0 | C4: (blank)
A5: =IFERROR(IF(VLOOKUP($C5,Data!$A:$D,4,0)="N",0,MAX(0,D5-Setup!$A$8)),) -> 0 | B5: =IFERROR(IF(VLOOKUP($C5,Data!$A:$D,4,0)="N",0,MAX(0,E5-Setup!$A$8)),) -> 0 | C5: A00000001 | D5: 1036.8 | E5: 0
A6: =IFERROR(IF(VLOOKUP($C6,Data!$A:$D,4,0)="N",0,MAX(0,D6-Setup!$A$8)),) -> 0 | B6: =IFERROR(IF(VLOOKUP($C6,Data!$A:$D,4,0)="N",0,MAX(0,E6-Setup!$A$8)),) -> 0 | C6: A00000002 | D6: 489.6 | E6: 0
A7: =IFERROR(IF(VLOOKUP($C7,Data!$A:$D,4,0)="N",0,MAX(0,D7-Setup!$A$8)),) -> 0 | B7: =IFERROR(IF(VLOOKUP($C7,Data!$A:$D,4,0)="N",0,MAX(0,E7-Setup!$A$8)),) -> 1800 | C7: A00000003 | D7: 0 | E7: 26300
A8: =IFERROR(IF(VLOOKUP($C8,Data!$A:$D,4,0)="N",0,MAX(0,D8-Setup!$A$8)),) -> 0 | B8: =IFERROR(IF(VLOOKUP($C8,Data!$A:$D,4,0)="N",0,MAX(0,E8-Setup!$A$8)),) -> 0 | C8: A00000004 | D8: 2295.76 | E8: 0
A9: =IFERROR(IF(VLOOKUP($C9,Data!$A:$D,4,0)="N",0,MAX(0,D9-Setup!$A$8)),) -> 0 | B9: =IFERROR(IF(VLOOKUP($C9,Data!$A:$D,4,0)="N",0,MAX(0,E9-Setup!$A$8)),) -> 0 | C9: A00000005 | D9: 3663 | E9: 4500
A10: =IFERROR(IF(VLOOKUP($C10,Data!$A:$D,4,0)="N",0,MAX(0,D10-Setup!$A$8)),) -> 0 | B10: =IFERROR(IF(VLOOKUP($C10,Data!$A:$D,4,0)="N",0,MAX(0,E10-Setup!$A$8)),) -> 0 | C10: A00000006 | D10: 1270.44 | E10: 1242
A11: =IFERROR(IF(VLOOKUP($C11,Data!$A:$D,4,0)="N",0,MAX(0,D11-Setup!$A$8)),) -> 0 | B11: =IFERROR(IF(VLOOKUP($C11,Data!$A:$D,4,0)="N",0,MAX(0,E11-Setup!$A$8)),) -> 0 | C11: A00000007 | D11: 0 | E11: 15750
A12: =IFERROR(IF(VLOOKUP($C12,Data!$A:$D,4,0)="N",0,MAX(0,D12-Setup!$A$8)),) -> 0 | B12: =IFERROR(IF(VLOOKUP($C12,Data!$A:$D,4,0)="N",0,MAX(0,E12-Setup!$A$8)),) -> 0 | C12: A00000008 | D12: 1595.52 | E12: 21412.44
A13: =IFERROR(IF(VLOOKUP($C13,Data!$A:$D,4,0)="N",0,MAX(0,D13-Setup!$A$8)),) -> 0 | B13: =IFERROR(IF(VLOOKUP($C13,Data!$A:$D,4,0)="N",0,MAX(0,E13-Setup!$A$8)),) -> 0 | C13: A00000009 | D13: 14517 | E13: 14571
A14: =IFERROR(IF(VLOOKUP($C14,Data!$A:$D,4,0)="N",0,MAX(0,D14-Setup!$A$8)),) -> 0 | B14: =IFERROR(IF(VLOOKUP($C14,Data!$A:$D,4,0)="N",0,MAX(0,E14-Setup!$A$8)),) -> 0 | C14: A00000010 | D14: 1288.98 | E14: 450
A15: =IFERROR(IF(VLOOKUP($C15,Data!$A:$D,4,0)="N",0,MAX(0,D15-Setup!$A$8)),) -> 0 | B15: =IFERROR(IF(VLOOKUP($C15,Data!$A:$D,4,0)="N",0,MAX(0,E15-Setup!$A$8)),) -> 0 | C15: A00000011 | D15: 3155.76 | E15: 911.7
A16: =IFERROR(IF(VLOOKUP($C16,Data!$A:$D,4,0)="N",0,MAX(0,D16-Setup!$A$8)),) -> 0 | B16: =IFERROR(IF(VLOOKUP($C16,Data!$A:$D,4,0)="N",0,MAX(0,E16-Setup!$A$8)),) -> 0 | C16: A00000012 | D16: 2970 | E16: 180
... A23: =IFERROR(IF(VLOOKUP($C23,Data!$A:$D,4,0)="N",0,MAX(0,D23-Setup!$A$8)),) -> 0 | B23: =IFERROR(IF(VLOOKUP($C23,Data!$A:$D,4,0)="N",0,MAX(0,E23-Setup!$A$8)),) -> 0 | C23: Grand Total | D23: 93052.96 | E23: 118767.14
